Workbook

Sheet Dashboard
B2: Inventory Risk & Forecast Dashboard
B3: 150 SKUs across 8 product categories — updated 09/04/2026
C5: Total SKU's | E5: Critical - Understock | G5: Critical - Overstock | I5: Avg Forecast Error | K5: Volatility - Error Correlation
C6: =COUNTA(InventoryModel[SKUID]) -> 150 | E6: =COUNTIF(InventoryModel[RiskTier],"CriticalUnderstock") -> 32 | G6: =COUNTIF(InventoryModel[RiskTier],"CriticalOverstock") -> 30 | I6: =AVERAGE(InventoryModel[AvgForecastError]) -> 0.15601625 | K6: =InventoryModel!Q2 -> 0.77466264
B23: SKUID | C23: Category | D23: SeverityRisk | E23: AvgForecastError
B24: SKU0055 | C24: Accessories | D24: 0.98861495 | E24: 0.36637343
B25: SKU0023 | C25: Chainsaws | D25: 0.98769201 | E25: 0.50134455
B26: SKU0018 | C26: Trimmers | D26: 0.98531383 | E26: 0.34739809
B27: SKU0138 | C27: Accessories | D27: 0.98091651 | E27: 0.39271639
B28: SKU0015 | C28: Trimmers | D28: 0.97646148 | E28: 0.51021044
B29: SKU0025 | C29: Mowers | D29: 0.97321603 | E29: 0.43666457
B30: SKU0094 | C30: Blowers | D30: 0.9672379 | E30: 0.51593349
B31: SKU0019 | C31: Small Parts | D31: 0.96663983 | E31: 1.9597677
B32: SKU0108 | C32: Batteries | D32: 0.95678228 | E32: 0.47316916
B33: SKU0150 | C33: Trimmers | D33: 0.95426308 | E33: 0.29349431

Sheet InventoryModel
A1: SKUID | B1: AnnualDemand | C1: EOQ | D1: AvgWeeklyDemand | E1: StdDevWeeklyDemand | F1: LeadTimeWeeksStdDev | G1: LeadTimeWeeks | H1: SafetyStock | I1: ReorderPoint | J1: CurrentStockLevel | K1: StockOutRisk | L1: SeverityRisk | M1: RiskTier | N1: AvgForecastError | O1: DemandCV | P1: Category | Q1: Correlation: Demand Volatility vs. Forecast Error
A2: SKU0001 | B2: =SUMIF(DemandHistory!A:A, A2, DemandHistory!C:C) * 2 -> 3230 | C2: =SQRT((2*B2*_xlfn.XLOOKUP(A2,SKU_Master!A:A,SKU_Master!E:E,,0))/_xlfn.XLOOKUP(A2,SKU_Master!A:A,SKU_Master!F:F,,0)) -> 58.469535 | D2: =_xlfn.XLOOKUP(InventoryModel[[#This Row],[SKUID]], DemandSummary!$A:$A, DemandSummary!$B:$B) -> 62.115385 | E2: =_xlfn.XLOOKUP(InventoryModel[[#This Row],[SKUID]],DemandSummary!A:A,DemandSummary!C:C,,0) -> 8.208907 | F2: =_xlfn.XLOOKUP(A2, SKU_Master[SKUID], SKU_Master[LeadTimeDaysStdDev], "Not Found", 0) / 7 -> 0.41428571 | G2: =_xlfn.XLOOKUP(A2, SKU_Master[SKUID], SKU_Master[LeadTimeDaysAvg], "Not Found", 0) / 7 -> 1.7142857 | H2: =1.65 * SQRT( (InventoryModel[[#This Row],[LeadTimeWeeks]] * (InventoryModel[[#This Row],[StdDevWeeklyDemand]]^2)) + ((InventoryModel[[#This Row],[AvgWeeklyDemand]]^2) * (InventoryModel[[#This Row],[LeadTimeWeeksStdDev]]^2)) ) -> 46.014977 | I2: =(InventoryModel[[#This Row],[AvgWeeklyDemand]] * InventoryModel[[#This Row],[LeadTimeWeeks]]) + InventoryModel[[#This Row],[SafetyStock]] -> 152.49849 | J2: =_xlfn.XLOOKUP(A2,SKU_Master[SKUID],SKU_Master[CurrentStockLevel],"Not Found", 0) -> 199 | K2: =IF(InventoryModel[[#This Row],[CurrentStockLevel]] < InventoryModel[[#This Row],[ReorderPoint]], "At Risk", "OK") -> OK | L2: =(InventoryModel[[#This Row],[ReorderPoint]] - InventoryModel[[#This Row],[CurrentStockLevel]]) / InventoryModel[[#This Row],[ReorderPoint]] -> -0.30493093 | M2: {=_xlfn.IFS( AND(InventoryModel[[#This Row],[StockOutRisk]]="At Risk", InventoryModel[[#This Row],[SeverityRisk]]>=0.6), "CriticalUnderstock", AND(InventoryModel[[#This Row],[StockOutRisk]]="At Risk", InventoryModel[[#This Row],[SeverityRisk]]>=0.2, InventoryModel[[#This Row],[SeverityRisk]]<0.6), "WatchUnderstock", AND(InventoryModel[[#This Row],[StockOutRisk]]="OK", InventoryModel[[#This Row],[SeverityRisk]]<=-0.2, InventoryModel[[#This Row],[SeverityRisk]]>-0.75), "WatchOverstock", AND(InventoryModel[[#This Row],[StockOutRisk]]="OK", InventoryModel[[#This Row],[SeverityRisk]]<=-0.75), "CriticalOverstock", TRUE, "Optimal" )} -> WatchOverstock | N2: =AVERAGEIFS(DemandHistory[AbsPctError],DemandHistory[SKUID],A2) -> 0.083947323 | O2: =InventoryModel[[#This Row],[StdDevWeeklyDemand]] / InventoryModel[[#This Row],[AvgWeeklyDemand]] -> 0.13215578 | P2: =_xlfn.XLOOKUP(A2, SKU_Master[SKUID], SKU_Master[Category], "Not Found", 0) -> Trimmers | Q2: =CORREL(InventoryModel[DemandCV], InventoryModel[AvgForecastError]) -> 0.77466264
A3: SKU0002 | B3: =SUMIF(DemandHistory!A:A, A3, DemandHistory!C:C) * 2 -> 4708 | C3: =SQRT((2*B3*_xlfn.XLOOKUP(A3,SKU_Master!A:A,SKU_Master!E:E,,0))/_xlfn.XLOOKUP(A3,SKU_Master!A:A,SKU_Master!F:F,,0)) -> 86.47771 | D3: =_xlfn.XLOOKUP(InventoryModel[[#This Row],[SKUID]], DemandSummary!$A:$A, DemandSummary!$B:$B) -> 90.538462 | E3: =_xlfn.XLOOKUP(InventoryModel[[#This Row],[SKUID]],DemandSummary!A:A,DemandSummary!C:C,,0) -> 19.561658 | F3: =_xlfn.XLOOKUP(A3, SKU_Master[SKUID], SKU_Master[LeadTimeDaysStdDev], "Not Found", 0) / 7 -> 0.38571429 | G3: =_xlfn.XLOOKUP(A3, SKU_Master[SKUID], SKU_Master[LeadTimeDaysAvg], "Not Found", 0) / 7 -> 0.85714286 | H3: =1.65 * SQRT( (InventoryModel[[#This Row],[LeadTimeWeeks]] * (InventoryModel[[#This Row],[StdDevWeeklyDemand]]^2)) + ((InventoryModel[[#This Row],[AvgWeeklyDemand]]^2) * (InventoryModel[[#This Row],[LeadTimeWeeksStdDev]]^2)) ) -> 64.908943 | I3: =(InventoryModel[[#This Row],[AvgWeeklyDemand]] * InventoryModel[[#This Row],[LeadTimeWeeks]]) + InventoryModel[[#This Row],[SafetyStock]] -> 142.51334 | J3: =_xlfn.XLOOKUP(A3,SKU_Master[SKUID],SKU_Master[CurrentStockLevel],"Not Found", 0) -> 84 | K3: =IF(InventoryModel[[#This Row],[CurrentStockLevel]] < InventoryModel[[#This Row],[ReorderPoint]], "At Risk", "OK") -> At Risk | L3: =(InventoryModel[[#This Row],[ReorderPoint]] - InventoryModel[[#This Row],[CurrentStockLevel]]) / InventoryModel[[#This Row],[ReorderPoint]] -> 0.41058149 | M3: {=_xlfn.IFS( AND(InventoryModel[[#This Row],[StockOutRisk]]="At Risk", InventoryModel[[#This Row],[SeverityRisk]]>=0.6), "CriticalUnderstock", AND(InventoryModel[[#This Row],[StockOutRisk]]="At Risk", InventoryModel[[#This Row],[SeverityRisk]]>=0.2, InventoryModel[[#This Row],[SeverityRisk]]<0.6), "WatchUnderstock", AND(InventoryModel[[#This Row],[StockOutRisk]]="OK", InventoryModel[[#This Row],[SeverityRisk]]<=-0.2, InventoryModel[[#This Row],[SeverityRisk]]>-0.75), "WatchOverstock", AND(InventoryModel[[#This Row],[StockOutRisk]]="OK", InventoryModel[[#This Row],[SeverityRisk]]<=-0.75), "CriticalOverstock", TRUE, "Optimal" )} -> WatchUnderstock | N3: =AVERAGEIFS(DemandHistory[AbsPctError],DemandHistory[SKUID],A3) -> 0.13980806 | O3: =InventoryModel[[#This Row],[StdDevWeeklyDemand]] / InventoryModel[[#This Row],[AvgWeeklyDemand]] -> 0.21605909 | P3: =_xlfn.XLOOKUP(A3, SKU_Master[SKUID], SKU_Master[Category], "Not Found", 0) -> Chainsaws | Q3: Median Forecast Error
A4: SKU0003 | B4: =SUMIF(DemandHistory!A:A, A4, DemandHistory!C:C) * 2 -> 5678 | C4: =SQRT((2*B4*_xlfn.XLOOKUP(A4,SKU_Master!A:A,SKU_Master!E:E,,0))/_xlfn.XLOOKUP(A4,SKU_Master!A:A,SKU_Master!F:F,,0)) -> 136.74414 | D4: =_xlfn.XLOOKUP(InventoryModel[[#This Row],[SKUID]], DemandSummary!$A:$A, DemandSummary!$B:$B) -> 109.19231 | E4: =_xlfn.XLOOKUP(InventoryModel[[#This Row],[SKUID]],DemandSummary!A:A,DemandSummary!C:C,,0) -> 16.928129 | F4: =_xlfn.XLOOKUP(A4, SKU_Master[SKUID], SKU_Master[LeadTimeDaysStdDev], "Not Found", 0) / 7 -> 0.18571429 | G4: =_xlfn.XLOOKUP(A4, SKU_Master[SKUID], SKU_Master[LeadTimeDaysAvg], "Not Found", 0) / 7 -> 1.4285714 | H4: =1.65 * SQRT( (InventoryModel[[#This Row],[LeadTimeWeeks]] * (InventoryModel[[#This Row],[StdDevWeeklyDemand]]^2)) + ((InventoryModel[[#This Row],[AvgWeeklyDemand]]^2) * (InventoryModel[[#This Row],[LeadTimeWeeksStdDev]]^2)) ) -> 47.265922 | I4: =(InventoryModel[[#This Row],[AvgWeeklyDemand]] * InventoryModel[[#This Row],[LeadTimeWeeks]]) + InventoryModel[[#This Row],[SafetyStock]] -> 203.25493 | J4: =_xlfn.XLOOKUP(A4,SKU_Master[SKUID],SKU_Master[CurrentStockLevel],"Not Found", 0) -> 196 | K4: =IF(InventoryModel[[#This Row],[CurrentStockLevel]] < InventoryModel[[#This Row],[ReorderPoint]], "At Risk", "OK") -> At Risk | L4: =(InventoryModel[[#This Row],[ReorderPoint]] - InventoryModel[[#This Row],[CurrentStockLevel]]) / InventoryModel[[#This Row],[ReorderPoint]] -> 0.035693762 | M4: {=_xlfn.IFS( AND(InventoryModel[[#This Row],[StockOutRisk]]="At Risk", InventoryModel[[#This Row],[SeverityRisk]]>=0.6), "CriticalUnderstock", AND(InventoryModel[[#This Row],[StockOutRisk]]="At Risk", InventoryModel[[#This Row],[SeverityRisk]]>=0.2, InventoryModel[[#This Row],[SeverityRisk]]<0.6), "WatchUnderstock", AND(InventoryModel[[#This Row],[StockOutRisk]]="OK", InventoryModel[[#This Row],[SeverityRisk]]<=-0.2, InventoryModel[[#This Row],[SeverityRisk]]>-0.75), "WatchOverstock", AND(InventoryModel[[#This Row],[StockOutRisk]]="OK", InventoryModel[[#This Row],[SeverityRisk]]<=-0.75), "CriticalOverstock", TRUE, "Optimal" )} -> Optimal | N4: =AVERAGEIFS(DemandHistory[AbsPctError],DemandHistory[SKUID],A4) -> 0.095881138 | O4: =InventoryModel[[#This Row],[StdDevWeeklyDemand]] / InventoryModel[[#This Row],[AvgWeeklyDemand]] -> 0.15503041 | P4: =_xlfn.XLOOKUP(A4, SKU_Master[SKUID], SKU_Master[Category], "Not Found", 0) -> Chains & Bars | Q4: =MEDIAN(InventoryModel[AvgForecastError]) -> 0.10832397
A5: SKU0004 | B5: =SUMIF(DemandHistory!A:A, A5, DemandHistory!C:C) * 2 -> 6762 | C5: =SQRT((2*B5*_xlfn.XLOOKUP(A5,SKU_Master!A:A,SKU_Master!E:E,,0))/_xlfn.XLOOKUP(A5,SKU_Master!A:A,SKU_Master!F:F,,0)) -> 194.22221 | D5: =_xlfn.XLOOKUP(InventoryModel[[#This Row],[SKUID]], DemandSummary!$A:$A, DemandSummary!$B:$B) -> 130.03846 | E5: =_xlfn.XLOOKUP(InventoryModel[[#This Row],[SKUID]],DemandSummary!A:A,DemandSummary!C:C,,0) -> 11.921345 | F5: =_xlfn.XLOOKUP(A5, SKU_Master[SKUID], SKU_Master[LeadTimeDaysStdDev], "Not Found", 0) / 7 -> 0.41428571 | G5: =_xlfn.XLOOKUP(A5, SKU_Master[SKUID], SKU_Master[LeadTimeDaysAvg], "Not Found", 0) / 7 -> 0.85714286 | H5: =1.65 * SQRT( (InventoryModel[[#This Row],[LeadTimeWeeks]] * (InventoryModel[[#This Row],[StdDevWeeklyDemand]]^2)) + ((InventoryModel[[#This Row],[AvgWeeklyDemand]]^2) * (InventoryModel[[#This Row],[LeadTimeWeeksStdDev]]^2)) ) -> 90.736863 | I5: =(InventoryModel[[#This Row],[AvgWeeklyDemand]] * InventoryModel[[#This Row],[LeadTimeWeeks]]) + InventoryModel[[#This Row],[SafetyStock]] -> 202.1984 | J5: =_xlfn.XLOOKUP(A5,SKU_Master[SKUID],SKU_Master[CurrentStockLevel],"Not Found", 0) -> 177 | K5: =IF(InventoryModel[[#This Row],[CurrentStockLevel]] < InventoryModel[[#This Row],[ReorderPoint]], "At Risk", "OK") -> At Risk | L5: =(InventoryModel[[#This Row],[ReorderPoint]] - InventoryModel[[#This Row],[CurrentStockLevel]]) / InventoryModel[[#This Row],[ReorderPoint]] -> 0.12462216 | M5: {=_xlfn.IFS( AND(InventoryModel[[#This Row],[StockOutRisk]]="At Risk", InventoryModel[[#This Row],[SeverityRisk]]>=0.6), "CriticalUnderstock", AND(InventoryModel[[#This Row],[StockOutRisk]]="At Risk", InventoryModel[[#This Row],[SeverityRisk]]>=0.2, InventoryModel[[#This Row],[SeverityRisk]]<0.6), "WatchUnderstock", AND(InventoryModel[[#This Row],[StockOutRisk]]="OK", InventoryModel[[#This Row],[SeverityRisk]]<=-0.2, InventoryModel[[#This Row],[SeverityRisk]]>-0.75), "WatchOverstock", AND(InventoryModel[[#This Row],[StockOutRisk]]="OK", InventoryModel[[#This Row],[SeverityRisk]]<=-0.75), "CriticalOverstock", TRUE, "Optimal" )} -> Optimal | N5: =AVERAGEIFS(DemandHistory[AbsPctError],DemandHistory[SKUID],A5) -> 0.063020134 | O5: =InventoryModel[[#This Row],[StdDevWeeklyDemand]] / InventoryModel[[#This Row],[AvgWeeklyDemand]] -> 0.091675529 | P5: =_xlfn.XLOOKUP(A5, SKU_Master[SKUID], SKU_Master[Category], "Not Found", 0) -> Blowers | Q5: Correlation: CurrentStock vs. ReorderPoint
A6: SKU0005 | B6: =SUMIF(DemandHistory!A:A, A6, DemandHistory!C:C) * 2 -> 4202 | C6: =SQRT((2*B6*_xlfn.XLOOKUP(A6,SKU_Master!A:A,SKU_Master!E:E,,0))/_xlfn.XLOOKUP(A6,SKU_Master!A:A,SKU_Master!F:F,,0)) -> 75.543408 | D6: =_xlfn.XLOOKUP(InventoryModel[[#This Row],[SKUID]], DemandSummary!$A:$A, DemandSummary!$B:$B) -> 80.807692 | E6: =_xlfn.XLOOKUP(InventoryModel[[#This Row],[SKUID]],DemandSummary!A:A,DemandSummary!C:C,,0) -> 12.778166 | F6: =_xlfn.XLOOKUP(A6, SKU_Master[SKUID], SKU_Master[LeadTimeDaysStdDev], "Not Found", 0) / 7 -> 0.27142857 | G6: =_xlfn.XLOOKUP(A6, SKU_Master[SKUID], SKU_Master[LeadTimeDaysAvg], "Not Found", 0) / 7 -> 2.2857143 | H6: =1.65 * SQRT( (InventoryModel[[#This Row],[LeadTimeWeeks]] * (InventoryModel[[#This Row],[StdDevWeeklyDemand]]^2)) + ((InventoryModel[[#This Row],[AvgWeeklyDemand]]^2) * (InventoryModel[[#This Row],[LeadTimeWeeksStdDev]]^2)) ) -> 48.226711 | I6: =(InventoryModel[[#This Row],[AvgWeeklyDemand]] * InventoryModel[[#This Row],[LeadTimeWeeks]]) + InventoryModel[[#This Row],[SafetyStock]] -> 232.93001 | J6: =_xlfn.XLOOKUP(A6,SKU_Master[SKUID],SKU_Master[CurrentStockLevel],"Not Found", 0) -> 253 | K6: =IF(InventoryModel[[#This Row],[CurrentStockLevel]] < InventoryModel[[#This Row],[ReorderPoint]], "At Risk", "OK") -> OK | L6: =(InventoryModel[[#This Row],[ReorderPoint]] - InventoryModel[[#This Row],[CurrentStockLevel]]) / InventoryModel[[#This Row],[ReorderPoint]] -> -0.086163189 | M6: {=_xlfn.IFS( AND(InventoryModel[[#This Row],[StockOutRisk]]="At Risk", InventoryModel[[#This Row],[SeverityRisk]]>=0.6), "CriticalUnderstock", AND(InventoryModel[[#This Row],[StockOutRisk]]="At Risk", InventoryModel[[#This Row],[SeverityRisk]]>=0.2, InventoryModel[[#This Row],[SeverityRisk]]<0.6), "WatchUnderstock", AND(InventoryModel[[#This Row],[StockOutRisk]]="OK", InventoryModel[[#This Row],[SeverityRisk]]<=-0.2, InventoryModel[[#This Row],[SeverityRisk]]>-0.75), "WatchOverstock", AND(InventoryModel[[#This Row],[StockOutRisk]]="OK", InventoryModel[[#This Row],[SeverityRisk]]<=-0.75), "CriticalOverstock", TRUE, "Optimal" )} -> Optimal | N6: =AVERAGEIFS(DemandHistory[AbsPctError],DemandHistory[SKUID],A6) -> 0.096586676 | O6: =InventoryModel[[#This Row],[StdDevWeeklyDemand]] / InventoryModel[[#This Row],[AvgWeeklyDemand]] -> 0.15813057 | P6: =_xlfn.XLOOKUP(A6, SKU_Master[SKUID], SKU_Master[Category], "Not Found", 0) -> Batteries | Q6: =CORREL(InventoryModel[CurrentStockLevel], InventoryModel[ReorderPoint]) -> -0.41892253
A7: SKU0006 | B7: =SUMIF(DemandHistory!A:A, A7, DemandHistory!C:C) * 2 -> 3992 | C7: =SQRT((2*B7*_xlfn.XLOOKUP(A7,SKU_Master!A:A,SKU_Master!E:E,,0))/_xlfn.XLOOKUP(A7,SKU_Master!A:A,SKU_Master!F:F,,0)) -> 71.118407 | D7: =_xlfn.XLOOKUP(InventoryModel[[#This Row],[SKUID]], DemandSummary!$A:$A, DemandSummary!$B:$B) -> 76.769231 | E7: =_xlfn.XLOOKUP(InventoryModel[[#This Row],[SKUID]],DemandSummary!A:A,DemandSummary!C:C,,0) -> 11.483232 | F7: =_xlfn.XLOOKUP(A7, SKU_Master[SKUID], SKU_Master[LeadTimeDaysStdDev], "Not Found", 0) / 7 -> 0.51428571 | G7: =_xlfn.XLOOKUP(A7, SKU_Master[SKUID], SKU_Master[LeadTimeDaysAvg], "Not Found", 0) / 7 -> 2.8571429 | H7: =1.65 * SQRT( (InventoryModel[[#This Row],[LeadTimeWeeks]] * (InventoryModel[[#This Row],[StdDevWeeklyDemand]]^2)) + ((InventoryModel[[#This Row],[AvgWeeklyDemand]]^2) * (InventoryModel[[#This Row],[LeadTimeWeeksStdDev]]^2)) ) -> 72.591198 | I7: =(InventoryModel[[#This Row],[AvgWeeklyDemand]] * InventoryModel[[#This Row],[LeadTimeWeeks]]) + InventoryModel[[#This Row],[SafetyStock]] -> 291.93186 | J7: =_xlfn.XLOOKUP(A7,SKU_Master[SKUID],SKU_Master[CurrentStockLevel],"Not Found", 0) -> 236 | K7: =IF(InventoryModel[[#This Row],[CurrentStockLevel]] < InventoryModel[[#This Row],[ReorderPoint]], "At Risk", "OK") -> At Risk | L7: =(InventoryModel[[#This Row],[ReorderPoint]] - InventoryModel[[#This Row],[CurrentStockLevel]]) / InventoryModel[[#This Row],[ReorderPoint]] -> 0.19159217 | M7: {=_xlfn.IFS( AND(InventoryModel[[#This Row],[StockOutRisk]]="At Risk", InventoryModel[[#This Row],[SeverityRisk]]>=0.6), "CriticalUnderstock", AND(InventoryModel[[#This Row],[StockOutRisk]]="At Risk", InventoryModel[[#This Row],[SeverityRisk]]>=0.2, InventoryModel[[#This Row],[SeverityRisk]]<0.6), "WatchUnderstock", AND(InventoryModel[[#This Row],[StockOutRisk]]="OK", InventoryModel[[#This Row],[SeverityRisk]]<=-0.2, InventoryModel[[#This Row],[SeverityRisk]]>-0.75), "WatchOverstock", AND(InventoryModel[[#This Row],[StockOutRisk]]="OK", InventoryModel[[#This Row],[SeverityRisk]]<=-0.75), "CriticalOverstock", TRUE, "Optimal" )} -> Optimal | N7: =AVERAGEIFS(DemandHistory[AbsPctError],DemandHistory[SKUID],A7) -> 0.098842418 | O7: =InventoryModel[[#This Row],[StdDevWeeklyDemand]] / InventoryModel[[#This Row],[AvgWeeklyDemand]] -> 0.14958118 | P7: =_xlfn.XLOOKUP(A7, SKU_Master[SKUID], SKU_Master[Category], "Not Found", 0) -> Mowers
A8: SKU0007 | B8: =SUMIF(DemandHistory!A:A, A8, DemandHistory!C:C) * 2 -> 2934 | C8: =SQRT((2*B8*_xlfn.XLOOKUP(A8,SKU_Master!A:A,SKU_Master!E:E,,0))/_xlfn.XLOOKUP(A8,SKU_Master!A:A,SKU_Master!F:F,,0)) -> 173.59726 | D8: =_xlfn.XLOOKUP(InventoryModel[[#This Row],[SKUID]], DemandSummary!$A:$A, DemandSummary!$B:$B) -> 56.423077 | E8: =_xlfn.XLOOKUP(InventoryModel[[#This Row],[SKUID]],DemandSummary!A:A,DemandSummary!C:C,,0) -> 8.4908095 | F8: =_xlfn.XLOOKUP(A8, SKU_Master[SKUID], SKU_Master[LeadTimeDaysStdDev], "Not Found", 0) / 7 -> 0.21428571 | G8: =_xlfn.XLOOKUP(A8, SKU_Master[SKUID], SKU_Master[LeadTimeDaysAvg], "Not Found", 0) / 7 -> 2.5714286 | H8: =1.65 * SQRT( (InventoryModel[[#This Row],[LeadTimeWeeks]] * (InventoryModel[[#This Row],[StdDevWeeklyDemand]]^2)) + ((InventoryModel[[#This Row],[AvgWeeklyDemand]]^2) * (InventoryModel[[#This Row],[LeadTimeWeeksStdDev]]^2)) ) -> 30.044874 | I8: =(InventoryModel[[#This Row],[AvgWeeklyDemand]] * InventoryModel[[#This Row],[LeadTimeWeeks]]) + InventoryModel[[#This Row],[SafetyStock]] -> 175.13279 | J8: =_xlfn.XLOOKUP(A8,SKU_Master[SKUID],SKU_Master[CurrentStockLevel],"Not Found", 0) -> 137 | K8: =IF(InventoryModel[[#This Row],[CurrentStockLevel]] < InventoryModel[[#This Row],[ReorderPoint]], "At Risk", "OK") -> At Risk | L8: =(InventoryModel[[#This Row],[ReorderPoint]] - InventoryModel[[#This Row],[CurrentStockLevel]]) / InventoryModel[[#This Row],[ReorderPoint]] -> 0.21773642 | M8: {=_xlfn.IFS( AND(InventoryModel[[#This Row],[StockOutRisk]]="At Risk", InventoryModel[[#This Row],[SeverityRisk]]>=0.6), "CriticalUnderstock", AND(InventoryModel[[#This Row],[StockOutRisk]]="At Risk", InventoryModel[[#This Row],[SeverityRisk]]>=0.2, InventoryModel[[#This Row],[SeverityRisk]]<0.6), "WatchUnderstock", AND(InventoryModel[[#This Row],[StockOutRisk]]="OK", InventoryModel[[#This Row],[SeverityRisk]]<=-0.2, InventoryModel[[#This Row],[SeverityRisk]]>-0.75), "WatchOverstock", AND(InventoryModel[[#This Row],[StockOutRisk]]="OK", InventoryModel[[#This Row],[SeverityRisk]]<=-0.75), "CriticalOverstock", TRUE, "Optimal" )} -> WatchUnderstock | N8: =AVERAGEIFS(DemandHistory[AbsPctError],DemandHistory[SKUID],A8) -> 0.099001327 | O8: =InventoryModel[[#This Row],[StdDevWeeklyDemand]] / InventoryModel[[#This Row],[AvgWeeklyDemand]] -> 0.15048469 | P8: =_xlfn.XLOOKUP(A8, SKU_Master[SKUID], SKU_Master[Category], "Not Found", 0) -> Accessories
A9: SKU0008 | B9: =SUMIF(DemandHistory!A:A, A9, DemandHistory!C:C) * 2 -> 6174 | C9: =SQRT((2*B9*_xlfn.XLOOKUP(A9,SKU_Master!A:A,SKU_Master!E:E,,0))/_xlfn.XLOOKUP(A9,SKU_Master!A:A,SKU_Master!F:F,,0)) -> 81.164186 | D9: =_xlfn.XLOOKUP(InventoryModel[[#This Row],[SKUID]], DemandSummary!$A:$A, DemandSummary!$B:$B) -> 118.73077 | E9: =_xlfn.XLOOKUP(InventoryModel[[#This Row],[SKUID]],DemandSummary!A:A,DemandSummary!C:C,,0) -> 21.680512 | F9: =_xlfn.XLOOKUP(A9, SKU_Master[SKUID], SKU_Master[LeadTimeDaysStdDev], "Not Found", 0) / 7 -> 0.47142857 | G9: =_xlfn.XLOOKUP(A9, SKU_Master[SKUID], SKU_Master[LeadTimeDaysAvg], "Not Found", 0) / 7 -> 1 | H9: =1.65 * SQRT( (InventoryModel[[#This Row],[LeadTimeWeeks]] * (InventoryModel[[#This Row],[StdDevWeeklyDemand]]^2)) + ((InventoryModel[[#This Row],[AvgWeeklyDemand]]^2) * (InventoryModel[[#This Row],[LeadTimeWeeksStdDev]]^2)) ) -> 99.041653 | I9: =(InventoryModel[[#This Row],[AvgWeeklyDemand]] * InventoryModel[[#This Row],[LeadTimeWeeks]]) + InventoryModel[[#This Row],[SafetyStock]] -> 217.77242 | J9: =_xlfn.XLOOKUP(A9,SKU_Master[SKUID],SKU_Master[CurrentStockLevel],"Not Found", 0) -> 196 | K9: =IF(InventoryModel[[#This Row],[CurrentStockLevel]] < InventoryModel[[#This Row],[ReorderPoint]], "At Risk", "OK") -> At Risk | L9: =(InventoryModel[[#This Row],[ReorderPoint]] - InventoryModel[[#This Row],[CurrentStockLevel]]) / InventoryModel[[#This Row],[ReorderPoint]] -> 0.099977867 | M9: {=_xlfn.IFS( AND(InventoryModel[[#This Row],[StockOutRisk]]="At Risk", InventoryModel[[#This Row],[SeverityRisk]]>=0.6), "CriticalUnderstock", AND(InventoryModel[[#This Row],[StockOutRisk]]="At Risk", InventoryModel[[#This Row],[SeverityRisk]]>=0.2, InventoryModel[[#This Row],[SeverityRisk]]<0.6), "WatchUnderstock", AND(InventoryModel[[#This Row],[StockOutRisk]]="OK", InventoryModel[[#This Row],[SeverityRisk]]<=-0.2, InventoryModel[[#This Row],[SeverityRisk]]>-0.75), "WatchOverstock", AND(InventoryModel[[#This Row],[StockOutRisk]]="OK", InventoryModel[[#This Row],[SeverityRisk]]<=-0.75), "CriticalOverstock", TRUE, "Optimal" )} -> Optimal | N9: =AVERAGEIFS(DemandHistory[AbsPctError],DemandHistory[SKUID],A9) -> 0.13951843 | O9: =InventoryModel[[#This Row],[StdDevWeeklyDemand]] / InventoryModel[[#This Row],[AvgWeeklyDemand]] -> 0.18260231 | P9: =_xlfn.XLOOKUP(A9, SKU_Master[SKUID], SKU_Master[Category], "Not Found", 0) -> Mowers
A10: SKU0009 | B10: =SUMIF(DemandHistory!A:A, A10, DemandHistory!C:C) * 2 -> 1228 | C10: =SQRT((2*B10*_xlfn.XLOOKUP(A10,SKU_Master!A:A,SKU_Master!E:E,,0))/_xlfn.XLOOKUP(A10,SKU_Master!A:A,SKU_Master!F:F,,0)) -> 64.100284 | D10: =_xlfn.XLOOKUP(InventoryModel[[#This Row],[SKUID]], DemandSummary!$A:$A, DemandSummary!$B:$B) -> 23.615385 | E10: =_xlfn.XLOOKUP(InventoryModel[[#This Row],[SKUID]],DemandSummary!A:A,DemandSummary!C:C,,0) -> 2.9131004 | F10: =_xlfn.XLOOKUP(A10, SKU_Master[SKUID], SKU_Master[LeadTimeDaysStdDev], "Not Found", 0) / 7 -> 0.17142857 | G10: =_xlfn.XLOOKUP(A10, SKU_Master[SKUID], SKU_Master[LeadTimeDaysAvg], "Not Found", 0) / 7 -> 2.7142857 | H10: =1.65 * SQRT( (InventoryModel[[#This Row],[LeadTimeWeeks]] * (InventoryModel[[#This Row],[StdDevWeeklyDemand]]^2)) + ((InventoryModel[[#This Row],[AvgWeeklyDemand]]^2) * (InventoryModel[[#This Row],[LeadTimeWeeksStdDev]]^2)) ) -> 10.359976 | I10: =(InventoryModel[[#This Row],[AvgWeeklyDemand]] * InventoryModel[[#This Row],[LeadTimeWeeks]]) + InventoryModel[[#This Row],[SafetyStock]] -> 74.458877 | J10: =_xlfn.XLOOKUP(A10,SKU_Master[SKUID],SKU_Master[CurrentStockLevel],"Not Found", 0) -> 73 | K10: =IF(InventoryModel[[#This Row],[CurrentStockLevel]] < InventoryModel[[#This Row],[ReorderPoint]], "At Risk", "OK") -> At Risk | L10: =(InventoryModel[[#This Row],[ReorderPoint]] - InventoryModel[[#This Row],[CurrentStockLevel]]) / InventoryModel[[#This Row],[ReorderPoint]] -> 0.019593063 | M10: {=_xlfn.IFS( AND(InventoryModel[[#This Row],[StockOutRisk]]="At Risk", InventoryModel[[#This Row],[SeverityRisk]]>=0.6), "CriticalUnderstock", AND(InventoryModel[[#This Row],[StockOutRisk]]="At Risk", InventoryModel[[#This Row],[SeverityRisk]]>=0.2, InventoryModel[[#This Row],[SeverityRisk]]<0.6), "WatchUnderstock", AND(InventoryModel[[#This Row],[StockOutRisk]]="OK", InventoryModel[[#This Row],[SeverityRisk]]<=-0.2, InventoryModel[[#This Row],[SeverityRisk]]>-0.75), "WatchOverstock", AND(InventoryModel[[#This Row],[StockOutRisk]]="OK", InventoryModel[[#This Row],[SeverityRisk]]<=-0.75), "CriticalOverstock", TRUE, "Optimal" )} -> Optimal | N10: =AVERAGEIFS(DemandHistory[AbsPctError],DemandHistory[SKUID],A10) -> 0.071593085 | O10: =InventoryModel[[#This Row],[StdDevWeeklyDemand]] / InventoryModel[[#This Row],[AvgWeeklyDemand]] -> 0.12335604 | P10: =_xlfn.XLOOKUP(A10, SKU_Master[SKUID], SKU_Master[Category], "Not Found", 0) -> Small Parts
A11: SKU0010 | B11: =SUMIF(DemandHistory!A:A, A11, DemandHistory!C:C) * 2 -> 2776 | C11: =SQRT((2*B11*_xlfn.XLOOKUP(A11,SKU_Master!A:A,SKU_Master!E:E,,0))/_xlfn.XLOOKUP(A11,SKU_Master!A:A,SKU_Master!F:F,,0)) -> 118.53211 | D11: =_xlfn.XLOOKUP(InventoryModel[[#This Row],[SKUID]], DemandSummary!$A:$A, DemandSummary!$B:$B) -> 53.384615 | E11: =_xlfn.XLOOKUP(InventoryModel[[#This Row],[SKUID]],DemandSummary!A:A,DemandSummary!C:C,,0) -> 19.946081 | F11: =_xlfn.XLOOKUP(A11, SKU_Master[SKUID], SKU_Master[LeadTimeDaysStdDev], "Not Found", 0) / 7 -> 1.1285714 | G11: =_xlfn.XLOOKUP(A11, SKU_Master[SKUID], SKU_Master[LeadTimeDaysAvg], "Not Found", 0) / 7 -> 6.1428571 | H11: =1.65 * SQRT( (InventoryModel[[#This Row],[LeadTimeWeeks]] * (InventoryModel[[#This Row],[StdDevWeeklyDemand]]^2)) + ((InventoryModel[[#This Row],[AvgWeeklyDemand]]^2) * (InventoryModel[[#This Row],[LeadTimeWeeksStdDev]]^2)) ) -> 128.59182 | I11: =(InventoryModel[[#This Row],[AvgWeeklyDemand]] * InventoryModel[[#This Row],[LeadTimeWeeks]]) + InventoryModel[[#This Row],[SafetyStock]] -> 456.52588 | J11: =_xlfn.XLOOKUP(A11,SKU_Master[SKUID],SKU_Master[CurrentStockLevel],"Not Found", 0) -> 33 | K11: =IF(InventoryModel[[#This Row],[CurrentStockLevel]] < InventoryModel[[#This Row],[ReorderPoint]], "At Risk", "OK") -> At Risk | L11: =(InventoryModel[[#This Row],[ReorderPoint]] - InventoryModel[[#This Row],[CurrentStockLevel]]) / InventoryModel[[#This Row],[ReorderPoint]] -> 0.92771494 | M11: {=_xlfn.IFS( AND(InventoryModel[[#This Row],[StockOutRisk]]="At Risk", InventoryModel[[#This Row],[SeverityRisk]]>=0.6), "CriticalUnderstock", AND(InventoryModel[[#This Row],[StockOutRisk]]="At Risk", InventoryModel[[#This Row],[SeverityRisk]]>=0.2, InventoryModel[[#This Row],[SeverityRisk]]<0.6), "WatchUnderstock", AND(InventoryModel[[#This Row],[StockOutRisk]]="OK", InventoryModel[[#This Row],[SeverityRisk]]<=-0.2, InventoryModel[[#This Row],[SeverityRisk]]>-0.75), "WatchOverstock", AND(InventoryModel[[#This Row],[StockOutRisk]]="OK", InventoryModel[[#This Row],[SeverityRisk]]<=-0.75), "CriticalOverstock", TRUE, "Optimal" )} -> CriticalUnderstock | N11: =AVERAGEIFS(DemandHistory[AbsPctError],DemandHistory[SKUID],A11) -> 0.32005504 | O11: =InventoryModel[[#This Row],[StdDevWeeklyDemand]] / InventoryModel[[#This Row],[AvgWeeklyDemand]] -> 0.37362976 | P11: =_xlfn.XLOOKUP(A11, SKU_Master[SKUID], SKU_Master[Category], "Not Found", 0) -> Chains & Bars
A12: SKU0011 | B12: =SUMIF(DemandHistory!A:A, A12, DemandHistory!C:C) * 2 -> 6434 | C12: =SQRT((2*B12*_xlfn.XLOOKUP(A12,SKU_Master!A:A,SKU_Master!E:E,,0))/_xlfn.XLOOKUP(A12,SKU_Master!A:A,SKU_Master!F:F,,0)) -> 147.13514 | D12: =_xlfn.XLOOKUP(InventoryModel[[#This Row],[SKUID]], DemandSummary!$A:$A, DemandSummary!$B:$B) -> 123.73077 | E12: =_xlfn.XLOOKUP(InventoryModel[[#This Row],[SKUID]],DemandSummary!A:A,DemandSummary!C:C,,0) -> 18.197929 | F12: =_xlfn.XLOOKUP(A12, SKU_Master[SKUID], SKU_Master[LeadTimeDaysStdDev], "Not Found", 0) / 7 -> 0.3 | G12: =_xlfn.XLOOKUP(A12, SKU_Master[SKUID], SKU_Master[LeadTimeDaysAvg], "Not Found", 0) / 7 -> 2.7142857 | H12: =1.65 * SQRT( (InventoryModel[[#This Row],[LeadTimeWeeks]] * (InventoryModel[[#This Row],[StdDevWeeklyDemand]]^2)) + ((InventoryModel[[#This Row],[AvgWeeklyDemand]]^2) * (InventoryModel[[#This Row],[LeadTimeWeeksStdDev]]^2)) ) -> 78.729602 | I12: =(InventoryModel[[#This Row],[AvgWeeklyDemand]] * InventoryModel[[#This Row],[LeadTimeWeeks]]) + InventoryModel[[#This Row],[SafetyStock]] -> 414.57026 | J12: =_xlfn.XLOOKUP(A12,SKU_Master[SKUID],SKU_Master[CurrentStockLevel],"Not Found", 0) -> 206 | K12: =IF(InventoryModel[[#This Row],[CurrentStockLevel]] < InventoryModel[[#This Row],[ReorderPoint]], "At Risk", "OK") -> At Risk | L12: =(InventoryModel[[#This Row],[ReorderPoint]] - InventoryModel[[#This Row],[CurrentStockLevel]]) / InventoryModel[[#This Row],[ReorderPoint]] -> 0.50309991 | M12: {=_xlfn.IFS( AND(InventoryModel[[#This Row],[StockOutRisk]]="At Risk", InventoryModel[[#This Row],[SeverityRisk]]>=0.6), "CriticalUnderstock", AND(InventoryModel[[#This Row],[StockOutRisk]]="At Risk", InventoryModel[[#This Row],[SeverityRisk]]>=0.2, InventoryModel[[#This Row],[SeverityRisk]]<0.6), "WatchUnderstock", AND(InventoryModel[[#This Row],[StockOutRisk]]="OK", InventoryModel[[#This Row],[SeverityRisk]]<=-0.2, InventoryModel[[#This Row],[SeverityRisk]]>-0.75), "WatchOverstock", AND(InventoryModel[[#This Row],[StockOutRisk]]="OK", InventoryModel[[#This Row],[SeverityRisk]]<=-0.75), "CriticalOverstock", TRUE, "Optimal" )} -> WatchUnderstock | N12: =AVERAGEIFS(DemandHistory[AbsPctError],DemandHistory[SKUID],A12) -> 0.13524464 | O12: =InventoryModel[[#This Row],[StdDevWeeklyDemand]] / InventoryModel[[#This Row],[AvgWeeklyDemand]] -> 0.14707683 | P12: =_xlfn.XLOOKUP(A12, SKU_Master[SKUID], SKU_Master[Category], "Not Found", 0) -> Chains & Bars
A13: SKU0012 | B13: =SUMIF(DemandHistory!A:A, A13, DemandHistory!C:C) * 2 -> 5080 | C13: =SQRT((2*B13*_xlfn.XLOOKUP(A13,SKU_Master!A:A,SKU_Master!E:E,,0))/_xlfn.XLOOKUP(A13,SKU_Master!A:A,SKU_Master!F:F,,0)) -> 103.97149 | D13: =_xlfn.XLOOKUP(InventoryModel[[#This Row],[SKUID]], DemandSummary!$A:$A, DemandSummary!$B:$B) -> 97.692308 | E13: =_xlfn.XLOOKUP(InventoryModel[[#This Row],[SKUID]],DemandSummary!A:A,DemandSummary!C:C,,0) -> 14.877551 | F13: =_xlfn.XLOOKUP(A13, SKU_Master[SKUID], SKU_Master[LeadTimeDaysStdDev], "Not Found", 0) / 7 -> 0.31428571 | G13: =_xlfn.XLOOKUP(A13, SKU_Master[SKUID], SKU_Master[LeadTimeDaysAvg], "Not Found", 0) / 7 -> 1.7142857 | H13: =1.65 * SQRT( (InventoryModel[[#This Row],[LeadTimeWeeks]] * (InventoryModel[[#This Row],[StdDevWeeklyDemand]]^2)) + ((InventoryModel[[#This Row],[AvgWeeklyDemand]]^2) * (InventoryModel[[#This Row],[LeadTimeWeeksStdDev]]^2)) ) -> 59.995939 | I13: =(InventoryModel[[#This Row],[AvgWeeklyDemand]] * InventoryModel[[#This Row],[LeadTimeWeeks]]) + InventoryModel[[#This Row],[SafetyStock]] -> 227.46847 | J13: =_xlfn.XLOOKUP(A13,SKU_Master[SKUID],SKU_Master[CurrentStockLevel],"Not Found", 0) -> 284 | K13: =IF(InventoryModel[[#This Row],[CurrentStockLevel]] < InventoryModel[[#This Row],[ReorderPoint]], "At Risk", "OK") -> OK | L13: =(InventoryModel[[#This Row],[ReorderPoint]] - InventoryModel[[#This Row],[CurrentStockLevel]]) / InventoryModel[[#This Row],[ReorderPoint]] -> -0.2485247 | M13: {=_xlfn.IFS( AND(InventoryModel[[#This Row],[StockOutRisk]]="At Risk", InventoryModel[[#This Row],[SeverityRisk]]>=0.6), "CriticalUnderstock", AND(InventoryModel[[#This Row],[StockOutRisk]]="At Risk", InventoryModel[[#This Row],[SeverityRisk]]>=0.2, InventoryModel[[#This Row],[SeverityRisk]]<0.6), "WatchUnderstock", AND(InventoryModel[[#This Row],[StockOutRisk]]="OK", InventoryModel[[#This Row],[SeverityRisk]]<=-0.2, InventoryModel[[#This Row],[SeverityRisk]]>-0.75), "WatchOverstock", AND(InventoryModel[[#This Row],[StockOutRisk]]="OK", InventoryModel[[#This Row],[SeverityRisk]]<=-0.75), "CriticalOverstock", TRUE, "Optimal" )} -> WatchOverstock | N13: =AVERAGEIFS(DemandHistory[AbsPctError],DemandHistory[SKUID],A13) -> 0.10468492 | O13: =InventoryModel[[#This Row],[StdDevWeeklyDemand]] / InventoryModel[[#This Row],[AvgWeeklyDemand]] -> 0.1522899 | P13: =_xlfn.XLOOKUP(A13, SKU_Master[SKUID], SKU_Master[Category], "Not Found", 0) -> Trimmers | T13: 0
A14: SKU0013 | B14: =SUMIF(DemandHistory!A:A, A14, DemandHistory!C:C) * 2 -> 2352 | C14: =SQRT((2*B14*_xlfn.XLOOKUP(A14,SKU_Master!A:A,SKU_Master!E:E,,0))/_xlfn.XLOOKUP(A14,SKU_Master!A:A,SKU_Master!F:F,,0)) -> 178.14813 | D14: =_xlfn.XLOOKUP(InventoryModel[[#This Row],[SKUID]], DemandSummary!$A:$A, DemandSummary!$B:$B) -> 45.230769 | E14: =_xlfn.XLOOKUP(InventoryModel[[#This Row],[SKUID]],DemandSummary!A:A,DemandSummary!C:C,,0) -> 15.639201 | F14: =_xlfn.XLOOKUP(A14, SKU_Master[SKUID], SKU_Master[LeadTimeDaysStdDev], "Not Found", 0) / 7 -> 1.5571429 | G14: =_xlfn.XLOOKUP(A14, SKU_Master[SKUID], SKU_Master[LeadTimeDaysAvg], "Not Found", 0) / 7 -> 3.5714286 | H14: =1.65 * SQRT( (InventoryModel[[#This Row],[LeadTimeWeeks]] * (InventoryModel[[#This Row],[StdDevWeeklyDemand]]^2)) + ((InventoryModel[[#This Row],[AvgWeeklyDemand]]^2) * (InventoryModel[[#This Row],[LeadTimeWeeksStdDev]]^2)) ) -> 126.02814 | I14: =(InventoryModel[[#This Row],[AvgWeeklyDemand]] * InventoryModel[[#This Row],[LeadTimeWeeks]]) + InventoryModel[[#This Row],[SafetyStock]] -> 287.5666 | J14: =_xlfn.XLOOKUP(A14,SKU_Master[SKUID],SKU_Master[CurrentStockLevel],"Not Found", 0) -> 40 | K14: =IF(InventoryModel[[#This Row],[CurrentStockLevel]] < InventoryModel[[#This Row],[ReorderPoint]], "At Risk", "OK") -> At Risk | L14: =(InventoryModel[[#This Row],[ReorderPoint]] - InventoryModel[[#This Row],[CurrentStockLevel]]) / InventoryModel[[#This Row],[ReorderPoint]] -> 0.86090179 | M14: {=_xlfn.IFS( AND(InventoryModel[[#This Row],[StockOutRisk]]="At Risk", InventoryModel[[#This Row],[SeverityRisk]]>=0.6), "CriticalUnderstock", AND(InventoryModel[[#This Row],[StockOutRisk]]="At Risk", InventoryModel[[#This Row],[SeverityRisk]]>=0.2, InventoryModel[[#This Row],[SeverityRisk]]<0.6), "WatchUnderstock", AND(InventoryModel[[#This Row],[StockOutRisk]]="OK", InventoryModel[[#This Row],[SeverityRisk]]<=-0.2, InventoryModel[[#This Row],[SeverityRisk]]>-0.75), "WatchOverstock", AND(InventoryModel[[#This Row],[StockOutRisk]]="OK", InventoryModel[[#This Row],[SeverityRisk]]<=-0.75), "CriticalOverstock", TRUE, "Optimal" )} -> CriticalUnderstock | N14: =AVERAGEIFS(DemandHistory[AbsPctError],DemandHistory[SKUID],A14) -> 0.27831971 | O14: =InventoryModel[[#This Row],[StdDevWeeklyDemand]] / InventoryModel[[#This Row],[AvgWeeklyDemand]] -> 0.34576465 | P14: =_xlfn.XLOOKUP(A14, SKU_Master[SKUID], SKU_Master[Category], "Not Found", 0) -> Accessories
A15: SKU0014 | B15: =SUMIF(DemandHistory!A:A, A15, DemandHistory!C:C) * 2 -> 5626 | C15: =SQRT((2*B15*_xlfn.XLOOKUP(A15,SKU_Master!A:A,SKU_Master!E:E,,0))/_xlfn.XLOOKUP(A15,SKU_Master!A:A,SKU_Master!F:F,,0)) -> 129.16675 | D15: =_xlfn.XLOOKUP(InventoryModel[[#This Row],[SKUID]], DemandSummary!$A:$A, DemandSummary!$B:$B) -> 108.19231 | E15: =_xlfn.XLOOKUP(InventoryModel[[#This Row],[SKUID]],DemandSummary!A:A,DemandSummary!C:C,,0) -> 12.890366 | F15: =_xlfn.XLOOKUP(A15, SKU_Master[SKUID], SKU_Master[LeadTimeDaysStdDev], "Not Found", 0) / 7 -> 0.55714286 | G15: =_xlfn.XLOOKUP(A15, SKU_Master[SKUID], SKU_Master[LeadTimeDaysAvg], "Not Found", 0) / 7 -> 2.4285714 | H15: =1.65 * SQRT( (InventoryModel[[#This Row],[LeadTimeWeeks]] * (InventoryModel[[#This Row],[StdDevWeeklyDemand]]^2)) + ((InventoryModel[[#This Row],[AvgWeeklyDemand]]^2) * (InventoryModel[[#This Row],[LeadTimeWeeksStdDev]]^2)) ) -> 104.83723 | I15: =(InventoryModel[[#This Row],[AvgWeeklyDemand]] * InventoryModel[[#This Row],[LeadTimeWeeks]]) + InventoryModel[[#This Row],[SafetyStock]] -> 367.58998 | J15: =_xlfn.XLOOKUP(A15,SKU_Master[SKUID],SKU_Master[CurrentStockLevel],"Not Found", 0) -> 88 | K15: =IF(InventoryModel[[#This Row],[CurrentStockLevel]] < InventoryModel[[#This Row],[ReorderPoint]], "At Risk", "OK") -> At Risk | L15: =(InventoryModel[[#This Row],[ReorderPoint]] - InventoryModel[[#This Row],[CurrentStockLevel]]) / InventoryModel[[#This Row],[ReorderPoint]] -> 0.76060283 | M15: {=_xlfn.IFS( AND(InventoryModel[[#This Row],[StockOutRisk]]="At Risk", InventoryModel[[#This Row],[SeverityRisk]]>=0.6), "CriticalUnderstock", AND(InventoryModel[[#This Row],[StockOutRisk]]="At Risk", InventoryModel[[#This Row],[SeverityRisk]]>=0.2, InventoryModel[[#This Row],[SeverityRisk]]<0.6), "WatchUnderstock", AND(InventoryModel[[#This Row],[StockOutRisk]]="OK", InventoryModel[[#This Row],[SeverityRisk]]<=-0.2, InventoryModel[[#This Row],[SeverityRisk]]>-0.75), "WatchOverstock", AND(InventoryModel[[#This Row],[StockOutRisk]]="OK", InventoryModel[[#This Row],[SeverityRisk]]<=-0.75), "CriticalOverstock", TRUE, "Optimal" )} -> CriticalUnderstock | N15: =AVERAGEIFS(DemandHistory[AbsPctError],DemandHistory[SKUID],A15) -> 0.083640177 | O15: =InventoryModel[[#This Row],[StdDevWeeklyDemand]] / InventoryModel[[#This Row],[AvgWeeklyDemand]] -> 0.11914309 | P15: =_xlfn.XLOOKUP(A15, SKU_Master[SKUID], SKU_Master[Category], "Not Found", 0) -> Chains & Bars
A16: SKU0015 | B16: =SUMIF(DemandHistory!A:A, A16, DemandHistory!C:C) * 2 -> 4362 | C16: =SQRT((2*B16*_xlfn.XLOOKUP(A16,SKU_Master!A:A,SKU_Master!E:E,,0))/_xlfn.XLOOKUP(A16,SKU_Master!A:A,SKU_Master!F:F,,0)) -> 158.57379 | D16: =_xlfn.XLOOKUP(InventoryModel[[#This Row],[SKUID]], DemandSummary!$A:$A, DemandSummary!$B:$B) -> 83.884615 | E16: =_xlfn.XLOOKUP(InventoryModel[[#This Row],[SKUID]],DemandSummary!A:A,DemandSummary!C:C,,0) -> 32.026648 | F16: =_xlfn.XLOOKUP(A16, SKU_Master[SKUID], SKU_Master[LeadTimeDaysStdDev], "Not Found", 0) / 7 -> 1.5714286 | G16: =_xlfn.XLOOKUP(A16, SKU_Master[SKUID], SKU_Master[LeadTimeDaysAvg], "Not Found", 0) / 7 -> 5.1428571 | H16: =1.65 * SQRT( (InventoryModel[[#This Row],[LeadTimeWeeks]] * (InventoryModel[[#This Row],[StdDevWeeklyDemand]]^2)) + ((InventoryModel[[#This Row],[AvgWeeklyDemand]]^2) * (InventoryModel[[#This Row],[LeadTimeWeeksStdDev]]^2)) ) -> 248.33034 | I16: =(InventoryModel[[#This Row],[AvgWeeklyDemand]] * InventoryModel[[#This Row],[LeadTimeWeeks]]) + InventoryModel[[#This Row],[SafetyStock]] -> 679.73694 | J16: =_xlfn.XLOOKUP(A16,SKU_Master[SKUID],SKU_Master[CurrentStockLevel],"Not Found", 0) -> 16 | K16: =IF(InventoryModel[[#This Row],[CurrentStockLevel]] < InventoryModel[[#This Row],[ReorderPoint]], "At Risk", "OK") -> At Risk | L16: =(InventoryModel[[#This Row],[ReorderPoint]] - InventoryModel[[#This Row],[CurrentStockLevel]]) / InventoryModel[[#This Row],[ReorderPoint]] -> 0.97646148 | M16: {=_xlfn.IFS( AND(InventoryModel[[#This Row],[StockOutRisk]]="At Risk", InventoryModel[[#This Row],[SeverityRisk]]>=0.6), "CriticalUnderstock", AND(InventoryModel[[#This Row],[StockOutRisk]]="At Risk", InventoryModel[[#This Row],[SeverityRisk]]>=0.2, InventoryModel[[#This Row],[SeverityRisk]]<0.6), "WatchUnderstock", AND(InventoryModel[[#This Row],[StockOutRisk]]="OK", InventoryModel[[#This Row],[SeverityRisk]]<=-0.2, InventoryModel[[#This Row],[SeverityRisk]]>-0.75), "WatchOverstock", AND(InventoryModel[[#This Row],[StockOutRisk]]="OK", InventoryModel[[#This Row],[SeverityRisk]]<=-0.75), "CriticalOverstock", TRUE, "Optimal" )} -> CriticalUnderstock | N16: =AVERAGEIFS(DemandHistory[AbsPctError],DemandHistory[SKUID],A16) -> 0.51021044 | O16: =InventoryModel[[#This Row],[StdDevWeeklyDemand]] / InventoryModel[[#This Row],[AvgWeeklyDemand]] -> 0.38179406 | P16: =_xlfn.XLOOKUP(A16, SKU_Master[SKUID], SKU_Master[Category], "Not Found", 0) -> Trimmers
A17: SKU0016 | B17: =SUMIF(DemandHistory!A:A, A17, DemandHistory!C:C) * 2 -> 4352 | C17: =SQRT((2*B17*_xlfn.XLOOKUP(A17,SKU_Master!A:A,SKU_Master!E:E,,0))/_xlfn.XLOOKUP(A17,SKU_Master!A:A,SKU_Master!F:F,,0)) -> 105.28079 | D17: =_xlfn.XLOOKUP(InventoryModel[[#This Row],[SKUID]], DemandSummary!$A:$A, DemandSummary!$B:$B) -> 83.692308 | E17: =_xlfn.XLOOKUP(InventoryModel[[#This Row],[SKUID]],DemandSummary!A:A,DemandSummary!C:C,,0) -> 8.7853024 | F17: =_xlfn.XLOOKUP(A17, SKU_Master[SKUID], SKU_Master[LeadTimeDaysStdDev], "Not Found", 0) / 7 -> 0.55714286 | G17: =_xlfn.XLOOKUP(A17, SKU_Master[SKUID], SKU_Master[LeadTimeDaysAvg], "Not Found", 0) / 7 -> 2.1428571 | H17: =1.65 * SQRT( (InventoryModel[[#This Row],[LeadTimeWeeks]] * (InventoryModel[[#This Row],[StdDevWeeklyDemand]]^2)) + ((InventoryModel[[#This Row],[AvgWeeklyDemand]]^2) * (InventoryModel[[#This Row],[LeadTimeWeeksStdDev]]^2)) ) -> 79.809746 | I17: =(InventoryModel[[#This Row],[AvgWeeklyDemand]] * InventoryModel[[#This Row],[LeadTimeWeeks]]) + InventoryModel[[#This Row],[SafetyStock]] -> 259.15041 | J17: =_xlfn.XLOOKUP(A17,SKU_Master[SKUID],SKU_Master[CurrentStockLevel],"Not Found", 0) -> 226 | K17: =IF(InventoryModel[[#This Row],[CurrentStockLevel]] < InventoryModel[[#This Row],[ReorderPoint]], "At Risk", "OK") -> At Risk | L17: =(InventoryModel[[#This Row],[ReorderPoint]] - InventoryModel[[#This Row],[CurrentStockLevel]]) / InventoryModel[[#This Row],[ReorderPoint]] -> 0.12791956 | M17: {=_xlfn.IFS( AND(InventoryModel[[#This Row],[StockOutRisk]]="At Risk", InventoryModel[[#This Row],[SeverityRisk]]>=0.6), "CriticalUnderstock", AND(InventoryModel[[#This Row],[StockOutRisk]]="At Risk", InventoryModel[[#This Row],[SeverityRisk]]>=0.2, InventoryModel[[#This Row],[SeverityRisk]]<0.6), "WatchUnderstock", AND(InventoryModel[[#This Row],[StockOutRisk]]="OK", InventoryModel[[#This Row],[SeverityRisk]]<=-0.2, InventoryModel[[#This Row],[SeverityRisk]]>-0.75), "WatchOverstock", AND(InventoryModel[[#This Row],[StockOutRisk]]="OK", InventoryModel[[#This Row],[SeverityRisk]]<=-0.75), "CriticalOverstock", TRUE, "Optimal" )} -> Optimal | N17: =AVERAGEIFS(DemandHistory[AbsPctError],DemandHistory[SKUID],A17) -> 0.065346332 | O17: =InventoryModel[[#This Row],[StdDevWeeklyDemand]] / InventoryModel[[#This Row],[AvgWeeklyDemand]] -> 0.10497144 | P17: =_xlfn.XLOOKUP(A17, SKU_Master[SKUID], SKU_Master[Category], "Not Found", 0) -> Chains & Bars
A18: SKU0017 | B18: =SUMIF(DemandHistory!A:A, A18, DemandHistory!C:C) * 2 -> 5596 | C18: =SQRT((2*B18*_xlfn.XLOOKUP(A18,SKU_Master!A:A,SKU_Master!E:E,,0))/_xlfn.XLOOKUP(A18,SKU_Master!A:A,SKU_Master!F:F,,0)) -> 140.77063 | D18: =_xlfn.XLOOKUP(InventoryModel[[#This Row],[SKUID]], DemandSummary!$A:$A, DemandSummary!$B:$B) -> 107.61538 | E18: =_xlfn.XLOOKUP(InventoryModel[[#This Row],[SKUID]],DemandSummary!A:A,DemandSummary!C:C,,0) -> 15.738048 | F18: =_xlfn.XLOOKUP(A18, SKU_Master[SKUID], SKU_Master[LeadTimeDaysStdDev], "Not Found", 0) / 7 -> 0.31428571 | G18: =_xlfn.XLOOKUP(A18, SKU_Master[SKUID], SKU_Master[LeadTimeDaysAvg], "Not Found", 0) / 7 -> 2.4285714 | H18: =1.65 * SQRT( (InventoryModel[[#This Row],[LeadTimeWeeks]] * (InventoryModel[[#This Row],[StdDevWeeklyDemand]]^2)) + ((InventoryModel[[#This Row],[AvgWeeklyDemand]]^2) * (InventoryModel[[#This Row],[LeadTimeWeeksStdDev]]^2)) ) -> 68.934656 | I18: =(InventoryModel[[#This Row],[AvgWeeklyDemand]] * InventoryModel[[#This Row],[LeadTimeWeeks]]) + InventoryModel[[#This Row],[SafetyStock]] -> 330.2863 | J18: =_xlfn.XLOOKUP(A18,SKU_Master[SKUID],SKU_Master[CurrentStockLevel],"Not Found", 0) -> 150 | K18: =IF(InventoryModel[[#This Row],[CurrentStockLevel]] < InventoryModel[[#This Row],[ReorderPoint]], "At Risk", "OK") -> At Risk | L18: =(InventoryModel[[#This Row],[ReorderPoint]] - InventoryModel[[#This Row],[CurrentStockLevel]]) / InventoryModel[[#This Row],[ReorderPoint]] -> 0.54584856 | M18: {=_xlfn.IFS( AND(InventoryModel[[#This Row],[StockOutRisk]]="At Risk", InventoryModel[[#This Row],[SeverityRisk]]>=0.6), "CriticalUnderstock", AND(InventoryModel[[#This Row],[StockOutRisk]]="At Risk", InventoryModel[[#This Row],[SeverityRisk]]>=0.2, InventoryModel[[#This Row],[SeverityRisk]]<0.6), "WatchUnderstock", AND(InventoryModel[[#This Row],[StockOutRisk]]="OK", InventoryModel[[#This Row],[SeverityRisk]]<=-0.2, InventoryModel[[#This Row],[SeverityRisk]]>-0.75), "WatchOverstock", AND(InventoryModel[[#This Row],[StockOutRisk]]="OK", InventoryModel[[#This Row],[SeverityRisk]]<=-0.75), "CriticalOverstock", TRUE, "Optimal" )} -> WatchUnderstock | N18: =AVERAGEIFS(DemandHistory[AbsPctError],DemandHistory[SKUID],A18) -> 0.09637737 | O18: =InventoryModel[[#This Row],[StdDevWeeklyDemand]] / InventoryModel[[#This Row],[AvgWeeklyDemand]] -> 0.14624348 | P18: =_xlfn.XLOOKUP(A18, SKU_Master[SKUID], SKU_Master[Category], "Not Found", 0) -> Chainsaws
A19: SKU0018 | B19: =SUMIF(DemandHistory!A:A, A19, DemandHistory!C:C) * 2 -> 6844 | C19: =SQRT((2*B19*_xlfn.XLOOKUP(A19,SKU_Master!A:A,SKU_Master!E:E,,0))/_xlfn.XLOOKUP(A19,SKU_Master!A:A,SKU_Master!F:F,,0)) -> 147.33622 | D19: =_xlfn.XLOOKUP(InventoryModel[[#This Row],[SKUID]], DemandSummary!$A:$A, DemandSummary!$B:$B) -> 131.61538 | E19: =_xlfn.XLOOKUP(InventoryModel[[#This Row],[SKUID]],DemandSummary!A:A,DemandSummary!C:C,,0) -> 48.367821 | F19: =_xlfn.XLOOKUP(A19, SKU_Master[SKUID], SKU_Master[LeadTimeDaysStdDev], "Not Found", 0) / 7 -> 1.2285714 | G19: =_xlfn.XLOOKUP(A19, SKU_Master[SKUID], SKU_Master[LeadTimeDaysAvg], "Not Found", 0) / 7 -> 3.8571429 | H19: =1.65 * SQRT( (InventoryModel[[#This Row],[LeadTimeWeeks]] * (InventoryModel[[#This Row],[StdDevWeeklyDemand]]^2)) + ((InventoryModel[[#This Row],[AvgWeeklyDemand]]^2) * (InventoryModel[[#This Row],[LeadTimeWeeksStdDev]]^2)) ) -> 309.43599 | I19: =(InventoryModel[[#This Row],[AvgWeeklyDemand]] * InventoryModel[[#This Row],[LeadTimeWeeks]]) + InventoryModel[[#This Row],[SafetyStock]] -> 817.09533 | J19: =_xlfn.XLOOKUP(A19,SKU_Master[SKUID],SKU_Master[CurrentStockLevel],"Not Found", 0) -> 12 | K19: =IF(InventoryModel[[#This Row],[CurrentStockLevel]] < InventoryModel[[#This Row],[ReorderPoint]], "At Risk", "OK") -> At Risk | L19: =(InventoryModel[[#This Row],[ReorderPoint]] - InventoryModel[[#This Row],[CurrentStockLevel]]) / InventoryModel[[#This Row],[ReorderPoint]] -> 0.98531383 | M19: {=_xlfn.IFS( AND(InventoryModel[[#This Row],[StockOutRisk]]="At Risk", InventoryModel[[#This Row],[SeverityRisk]]>=0.6), "CriticalUnderstock", AND(InventoryModel[[#This Row],[StockOutRisk]]="At Risk", InventoryModel[[#This Row],[SeverityRisk]]>=0.2, InventoryModel[[#This Row],[SeverityRisk]]<0.6), "WatchUnderstock", AND(InventoryModel[[#This Row],[StockOutRisk]]="OK", InventoryModel[[#This Row],[SeverityRisk]]<=-0.2, InventoryModel[[#This Row],[SeverityRisk]]>-0.75), "WatchOverstock", AND(InventoryModel[[#This Row],[StockOutRisk]]="OK", InventoryModel[[#This Row],[SeverityRisk]]<=-0.75), "CriticalOverstock", TRUE, "Optimal" )} -> CriticalUnderstock | N19: =AVERAGEIFS(DemandHistory[AbsPctError],DemandHistory[SKUID],A19) -> 0.34739809 | O19: =InventoryModel[[#This Row],[StdDevWeeklyDemand]] / InventoryModel[[#This Row],[AvgWeeklyDemand]] -> 0.36749368 | P19: =_xlfn.XLOOKUP(A19, SKU_Master[SKUID], SKU_Master[Category], "Not Found", 0) -> Trimmers
A20: SKU0019 | B20: =SUMIF(DemandHistory!A:A, A20, DemandHistory!C:C) * 2 -> 5582 | C20: =SQRT((2*B20*_xlfn.XLOOKUP(A20,SKU_Master!A:A,SKU_Master!E:E,,0))/_xlfn.XLOOKUP(A20,SKU_Master!A:A,SKU_Master!F:F,,0)) -> 76.856043 | D20: =_xlfn.XLOOKUP(InventoryModel[[#This Row],[SKUID]], DemandSummary!$A:$A, DemandSummary!$B:$B) -> 107.34615 | E20: =_xlfn.XLOOKUP(InventoryModel[[#This Row],[SKUID]],DemandSummary!A:A,DemandSummary!C:C,,0) -> 50.672235 | F20: =_xlfn.XLOOKUP(A20, SKU_Master[SKUID], SKU_Master[LeadTimeDaysStdDev], "Not Found", 0) / 7 -> 0.94285714 | G20: =_xlfn.XLOOKUP(A20, SKU_Master[SKUID], SKU_Master[LeadTimeDaysAvg], "Not Found", 0) / 7 -> 5.4285714 | H20: =1.65 * SQRT( (InventoryModel[[#This Row],[LeadTimeWeeks]] * (InventoryModel[[#This Row],[StdDevWeeklyDemand]]^2)) + ((InventoryModel[[#This Row],[AvgWeeklyDemand]]^2) * (InventoryModel[[#This Row],[LeadTimeWeeksStdDev]]^2)) ) -> 256.58798 | I20: =(InventoryModel[[#This Row],[AvgWeeklyDemand]] * InventoryModel[[#This Row],[LeadTimeWeeks]]) + InventoryModel[[#This Row],[SafetyStock]] -> 839.32424 | J20: =_xlfn.XLOOKUP(A20,SKU_Master[SKUID],SKU_Master[CurrentStockLevel],"Not Found", 0) -> 28 | K20: =IF(InventoryModel[[#This Row],[CurrentStockLevel]] < InventoryModel[[#This Row],[ReorderPoint]], "At Risk", "OK") -> At Risk | L20: =(InventoryModel[[#This Row],[ReorderPoint]] - InventoryModel[[#This Row],[CurrentStockLevel]]) / InventoryModel[[#This Row],[ReorderPoint]] -> 0.96663983 | M20: {=_xlfn.IFS( AND(InventoryModel[[#This Row],[StockOutRisk]]="At Risk", InventoryModel[[#This Row],[SeverityRisk]]>=0.6), "CriticalUnderstock", AND(InventoryModel[[#This Row],[StockOutRisk]]="At Risk", InventoryModel[[#This Row],[SeverityRisk]]>=0.2, InventoryModel[[#This Row],[SeverityRisk]]<0.6), "WatchUnderstock", AND(InventoryModel[[#This Row],[StockOutRisk]]="OK", InventoryModel[[#This Row],[SeverityRisk]]<=-0.2, InventoryModel[[#This Row],[SeverityRisk]]>-0.75), "WatchOverstock", AND(InventoryModel[[#This Row],[StockOutRisk]]="OK", InventoryModel[[#This Row],[SeverityRisk]]<=-0.75), "CriticalOverstock", TRUE, "Optimal" )} -> CriticalUnderstock | N20: =AVERAGEIFS(DemandHistory[AbsPctError],DemandHistory[SKUID],A20) -> 1.9597677 | O20: =InventoryModel[[#This Row],[StdDevWeeklyDemand]] / InventoryModel[[#This Row],[AvgWeeklyDemand]] -> 0.47204518 | P20: =_xlfn.XLOOKUP(A20, SKU_Master[SKUID], SKU_Master[Category], "Not Found", 0) -> Small Parts
A21: SKU0020 | B21: =SUMIF(DemandHistory!A:A, A21, DemandHistory!C:C) * 2 -> 4654 | C21: =SQRT((2*B21*_xlfn.XLOOKUP(A21,SKU_Master!A:A,SKU_Master!E:E,,0))/_xlfn.XLOOKUP(A21,SKU_Master!A:A,SKU_Master!F:F,,0)) -> 225.26911 | D21: =_xlfn.XLOOKUP(InventoryModel[[#This Row],[SKUID]], DemandSummary!$A:$A, DemandSummary!$B:$B) -> 89.5 | E21: =_xlfn.XLOOKUP(InventoryModel[[#This Row],[SKUID]],DemandSummary!A:A,DemandSummary!C:C,,0) -> 14.230249 | F21: =_xlfn.XLOOKUP(A21, SKU_Master[SKUID], SKU_Master[LeadTimeDaysStdDev], "Not Found", 0) / 7 -> 0.55714286 | G21: =_xlfn.XLOOKUP(A21, SKU_Master[SKUID], SKU_Master[LeadTimeDaysAvg], "Not Found", 0) / 7 -> 1.8571429 | H21: =1.65 * SQRT( (InventoryModel[[#This Row],[LeadTimeWeeks]] * (InventoryModel[[#This Row],[StdDevWeeklyDemand]]^2)) + ((InventoryModel[[#This Row],[AvgWeeklyDemand]]^2) * (InventoryModel[[#This Row],[LeadTimeWeeksStdDev]]^2)) ) -> 88.279139 | I21: =(InventoryModel[[#This Row],[AvgWeeklyDemand]] * InventoryModel[[#This Row],[LeadTimeWeeks]]) + InventoryModel[[#This Row],[SafetyStock]] -> 254.49342 | J21: =_xlfn.XLOOKUP(A21,SKU_Master[SKUID],SKU_Master[CurrentStockLevel],"Not Found", 0) -> 204 | K21: =IF(InventoryModel[[#This Row],[CurrentStockLevel]] < InventoryModel[[#This Row],[ReorderPoint]], "At Risk", "OK") -> At Risk | L21: =(InventoryModel[[#This Row],[ReorderPoint]] - InventoryModel[[#This Row],[CurrentStockLevel]]) / InventoryModel[[#This Row],[ReorderPoint]] -> 0.19840758 | M21: {=_xlfn.IFS( AND(InventoryModel[[#This Row],[StockOutRisk]]="At Risk", InventoryModel[[#This Row],[SeverityRisk]]>=0.6), "CriticalUnderstock", AND(InventoryModel[[#This Row],[StockOutRisk]]="At Risk", InventoryModel[[#This Row],[SeverityRisk]]>=0.2, InventoryModel[[#This Row],[SeverityRisk]]<0.6), "WatchUnderstock", AND(InventoryModel[[#This Row],[StockOutRisk]]="OK", InventoryModel[[#This Row],[SeverityRisk]]<=-0.2, InventoryModel[[#This Row],[SeverityRisk]]>-0.75), "WatchOverstock", AND(InventoryModel[[#This Row],[StockOutRisk]]="OK", InventoryModel[[#This Row],[SeverityRisk]]<=-0.75), "CriticalOverstock", TRUE, "Optimal" )} -> Optimal | N21: =AVERAGEIFS(DemandHistory[AbsPctError],DemandHistory[SKUID],A21) -> 0.1103873 | O21: =InventoryModel[[#This Row],[StdDevWeeklyDemand]] / InventoryModel[[#This Row],[AvgWeeklyDemand]] -> 0.1589972 | P21: =_xlfn.XLOOKUP(A21, SKU_Master[SKUID], SKU_Master[Category], "Not Found", 0) -> Chainsaws
A22: SKU0021 | B22: =SUMIF(DemandHistory!A:A, A22, DemandHistory!C:C) * 2 -> 4484 | C22: =SQRT((2*B22*_xlfn.XLOOKUP(A22,SKU_Master!A:A,SKU_Master!E:E,,0))/_xlfn.XLOOKUP(A22,SKU_Master!A:A,SKU_Master!F:F,,0)) -> 82.077842 | D22: =_xlfn.XLOOKUP(InventoryModel[[#This Row],[SKUID]], DemandSummary!$A:$A, DemandSummary!$B:$B) -> 86.230769 | E22: =_xlfn.XLOOKUP(InventoryModel[[#This Row],[SKUID]],DemandSummary!A:A,DemandSummary!C:C,,0) -> 12.371929 | F22: =_xlfn.XLOOKUP(A22, SKU_Master[SKUID], SKU_Master[LeadTimeDaysStdDev], "Not Found", 0) / 7 -> 0.34285714 | G22: =_xlfn.XLOOKUP(A22, SKU_Master[SKUID], SKU_Master[LeadTimeDaysAvg], "Not Found", 0) / 7 -> 2.7142857 | H22: =1.65 * SQRT( (InventoryModel[[#This Row],[LeadTimeWeeks]] * (InventoryModel[[#This Row],[StdDevWeeklyDemand]]^2)) + ((InventoryModel[[#This Row],[AvgWeeklyDemand]]^2) * (InventoryModel[[#This Row],[LeadTimeWeeksStdDev]]^2)) ) -> 59.251787 | I22: =(InventoryModel[[#This Row],[AvgWeeklyDemand]] * InventoryModel[[#This Row],[LeadTimeWeeks]]) + InventoryModel[[#This Row],[SafetyStock]] -> 293.30673 | J22: =_xlfn.XLOOKUP(A22,SKU_Master[SKUID],SKU_Master[CurrentStockLevel],"Not Found", 0) -> 129 | K22: =IF(InventoryModel[[#This Row],[CurrentStockLevel]] < InventoryModel[[#This Row],[ReorderPoint]], "At Risk", "OK") -> At Risk | L22: =(InventoryModel[[#This Row],[ReorderPoint]] - InventoryModel[[#This Row],[CurrentStockLevel]]) / InventoryModel[[#This Row],[ReorderPoint]] -> 0.56018739 | M22: {=_xlfn.IFS( AND(InventoryModel[[#This Row],[StockOutRisk]]="At Risk", InventoryModel[[#This Row],[SeverityRisk]]>=0.6), "CriticalUnderstock", AND(InventoryModel[[#This Row],[StockOutRisk]]="At Risk", InventoryModel[[#This Row],[SeverityRisk]]>=0.2, InventoryModel[[#This Row],[SeverityRisk]]<0.6), "WatchUnderstock", AND(InventoryModel[[#This Row],[StockOutRisk]]="OK", InventoryModel[[#This Row],[SeverityRisk]]<=-0.2, InventoryModel[[#This Row],[SeverityRisk]]>-0.75), "WatchOverstock", AND(InventoryModel[[#This Row],[StockOutRisk]]="OK", InventoryModel[[#This Row],[SeverityRisk]]<=-0.75), "CriticalOverstock", TRUE, "Optimal" )} -> WatchUnderstock | N22: =AVERAGEIFS(DemandHistory[AbsPctError],DemandHistory[SKUID],A22) -> 0.10016878 | O22: =InventoryModel[[#This Row],[StdDevWeeklyDemand]] / InventoryModel[[#This Row],[AvgWeeklyDemand]] -> 0.14347464 | P22: =_xlfn.XLOOKUP(A22, SKU_Master[SKUID], SKU_Master[Category], "Not Found", 0) -> Small Parts
A23: SKU0022 | B23: =SUMIF(DemandHistory!A:A, A23, DemandHistory!C:C) * 2 -> 4268 | C23: =SQRT((2*B23*_xlfn.XLOOKUP(A23,SKU_Master!A:A,SKU_Master!E:E,,0))/_xlfn.XLOOKUP(A23,SKU_Master!A:A,SKU_Master!F:F,,0)) -> 209.91184 | D23: =_xlfn.XLOOKUP(InventoryModel[[#This Row],[SKUID]], DemandSummary!$A:$A, DemandSummary!$B:$B) -> 82.076923 | E23: =_xlfn.XLOOKUP(InventoryModel[[#This Row],[SKUID]],DemandSummary!A:A,DemandSummary!C:C,,0) -> 13.02282 | F23: =_xlfn.XLOOKUP(A23, SKU_Master[SKUID], SKU_Master[LeadTimeDaysStdDev], "Not Found", 0) / 7 -> 0.5 | G23: =_xlfn.XLOOKUP(A23, SKU_Master[SKUID], SKU_Master[LeadTimeDaysAvg], "Not Found", 0) / 7 -> 2.8571429 | H23: =1.65 * SQRT( (InventoryModel[[#This Row],[LeadTimeWeeks]] * (InventoryModel[[#This Row],[StdDevWeeklyDemand]]^2)) + ((InventoryModel[[#This Row],[AvgWeeklyDemand]]^2) * (InventoryModel[[#This Row],[LeadTimeWeeksStdDev]]^2)) ) -> 76.839513 | I23: =(InventoryModel[[#This Row],[AvgWeeklyDemand]] * InventoryModel[[#This Row],[LeadTimeWeeks]]) + InventoryModel[[#This Row],[SafetyStock]] -> 311.34501 | J23: =_xlfn.XLOOKUP(A23,SKU_Master[SKUID],SKU_Master[CurrentStockLevel],"Not Found", 0) -> 91 | K23: =IF(InventoryModel[[#This Row],[CurrentStockLevel]] < InventoryModel[[#This Row],[ReorderPoint]], "At Risk", "OK") -> At Risk | L23: =(InventoryModel[[#This Row],[ReorderPoint]] - InventoryModel[[#This Row],[CurrentStockLevel]]) / InventoryModel[[#This Row],[ReorderPoint]] -> 0.70771974 | M23: {=_xlfn.IFS( AND(InventoryModel[[#This Row],[StockOutRisk]]="At Risk", InventoryModel[[#This Row],[SeverityRisk]]>=0.6), "CriticalUnderstock", AND(InventoryModel[[#This Row],[StockOutRisk]]="At Risk", InventoryModel[[#This Row],[SeverityRisk]]>=0.2, InventoryModel[[#This Row],[SeverityRisk]]<0.6), "WatchUnderstock", AND(InventoryModel[[#This Row],[StockOutRisk]]="OK", InventoryModel[[#This Row],[SeverityRisk]]<=-0.2, InventoryModel[[#This Row],[SeverityRisk]]>-0.75), "WatchOverstock", AND(InventoryModel[[#This Row],[StockOutRisk]]="OK", InventoryModel[[#This Row],[SeverityRisk]]<=-0.75), "CriticalOverstock", TRUE, "Optimal" )} -> CriticalUnderstock | N23: =AVERAGEIFS(DemandHistory[AbsPctError],DemandHistory[SKUID],A23) -> 0.094102287 | O23: =InventoryModel[[#This Row],[StdDevWeeklyDemand]] / InventoryModel[[#This Row],[AvgWeeklyDemand]] -> 0.15866604 | P23: =_xlfn.XLOOKUP(A23, SKU_Master[SKUID], SKU_Master[Category], "Not Found", 0) -> Trimmers
A24: SKU0023 | B24: =SUMIF(DemandHistory!A:A, A24, DemandHistory!C:C) * 2 -> 2862 | C24: =SQRT((2*B24*_xlfn.XLOOKUP(A24,SKU_Master!A:A,SKU_Master!E:E,,0))/_xlfn.XLOOKUP(A24,SKU_Master!A:A,SKU_Master!F:F,,0)) -> 182.95926 | D24: =_xlfn.XLOOKUP(InventoryModel[[#This Row],[SKUID]], DemandSummary!$A:$A, DemandSummary!$B:$B) -> 55.038462 | E24: =_xlfn.XLOOKUP(InventoryModel[[#This Row],[SKUID]],DemandSummary!A:A,DemandSummary!C:C,,0) -> 21.543409 | F24: =_xlfn.XLOOKUP(A24, SKU_Master[SKUID], SKU_Master[LeadTimeDaysStdDev], "Not Found", 0) / 7 -> 1.3285714 | G24: =_xlfn.XLOOKUP(A24, SKU_Master[SKUID], SKU_Master[LeadTimeDaysAvg], "Not Found", 0) / 7 -> 6.1428571 | H24: =1.65 * SQRT( (InventoryModel[[#This Row],[LeadTimeWeeks]] * (InventoryModel[[#This Row],[StdDevWeeklyDemand]]^2)) + ((InventoryModel[[#This Row],[AvgWeeklyDemand]]^2) * (InventoryModel[[#This Row],[LeadTimeWeeksStdDev]]^2)) ) -> 149.39488 | I24: =(InventoryModel[[#This Row],[AvgWeeklyDemand]] * InventoryModel[[#This Row],[LeadTimeWeeks]]) + InventoryModel[[#This Row],[SafetyStock]] -> 487.48829 | J24: =_xlfn.XLOOKUP(A24,SKU_Master[SKUID],SKU_Master[CurrentStockLevel],"Not Found", 0) -> 6 | K24: =IF(InventoryModel[[#This Row],[CurrentStockLevel]] < InventoryModel[[#This Row],[ReorderPoint]], "At Risk", "OK") -> At Risk | L24: =(InventoryModel[[#This Row],[ReorderPoint]] - InventoryModel[[#This Row],[CurrentStockLevel]]) / InventoryModel[[#This Row],[ReorderPoint]] -> 0.98769201 | M24: {=_xlfn.IFS( AND(InventoryModel[[#This Row],[StockOutRisk]]="At Risk", InventoryModel[[#This Row],[SeverityRisk]]>=0.6), "CriticalUnderstock", AND(InventoryModel[[#This Row],[StockOutRisk]]="At Risk", InventoryModel[[#This Row],[SeverityRisk]]>=0.2, InventoryModel[[#This Row],[SeverityRisk]]<0.6), "WatchUnderstock", AND(InventoryModel[[#This Row],[StockOutRisk]]="OK", InventoryModel[[#This Row],[SeverityRisk]]<=-0.2, InventoryModel[[#This Row],[SeverityRisk]]>-0.75), "WatchOverstock", AND(InventoryModel[[#This Row],[StockOutRisk]]="OK", InventoryModel[[#This Row],[SeverityRisk]]<=-0.75), "CriticalOverstock", TRUE, "Optimal" )} -> CriticalUnderstock | N24: =AVERAGEIFS(DemandHistory[AbsPctError],DemandHistory[SKUID],A24) -> 0.50134455 | O24: =InventoryModel[[#This Row],[StdDevWeeklyDemand]] / InventoryModel[[#This Row],[AvgWeeklyDemand]] -> 0.39142462 | P24: =_xlfn.XLOOKUP(A24, SKU_Master[SKUID], SKU_Master[Category], "Not Found", 0) -> Chainsaws
A25: SKU0024 | B25: =SUMIF(DemandHistory!A:A, A25, DemandHistory!C:C) * 2 -> 1598 | C25: =SQRT((2*B25*_xlfn.XLOOKUP(A25,SKU_Master!A:A,SKU_Master!E:E,,0))/_xlfn.XLOOKUP(A25,SKU_Master!A:A,SKU_Master!F:F,,0)) -> 55.73176 | D25: =_xlfn.XLOOKUP(InventoryModel[[#This Row],[SKUID]], DemandSummary!$A:$A, DemandSummary!$B:$B) -> 30.730769 | E25: =_xlfn.XLOOKUP(InventoryModel[[#This Row],[SKUID]],DemandSummary!A:A,DemandSummary!C:C,,0) -> 3.6721404 | F25: =_xlfn.XLOOKUP(A25, SKU_Master[SKUID], SKU_Master[LeadTimeDaysStdDev], "Not Found", 0) / 7 -> 0.37142857 | G25: =_xlfn.XLOOKUP(A25, SKU_Master[SKUID], SKU_Master[LeadTimeDaysAvg], "Not Found", 0) / 7 -> 1.8571429 | H25: =1.65 * SQRT( (InventoryModel[[#This Row],[LeadTimeWeeks]] * (InventoryModel[[#This Row],[StdDevWeeklyDemand]]^2)) + ((InventoryModel[[#This Row],[AvgWeeklyDemand]]^2) * (InventoryModel[[#This Row],[LeadTimeWeeksStdDev]]^2)) ) -> 20.564109 | I25: =(InventoryModel[[#This Row],[AvgWeeklyDemand]] * InventoryModel[[#This Row],[LeadTimeWeeks]]) + InventoryModel[[#This Row],[SafetyStock]] -> 77.635538 | J25: =_xlfn.XLOOKUP(A25,SKU_Master[SKUID],SKU_Master[CurrentStockLevel],"Not Found", 0) -> 282 | K25: =IF(InventoryModel[[#This Row],[CurrentStockLevel]] < InventoryModel[[#This Row],[ReorderPoint]], "At Risk", "OK") -> OK | L25: =(InventoryModel[[#This Row],[ReorderPoint]] - InventoryModel[[#This Row],[CurrentStockLevel]]) / InventoryModel[[#This Row],[ReorderPoint]] -> -2.6323571 | M25: {=_xlfn.IFS( AND(InventoryModel[[#This Row],[StockOutRisk]]="At Risk", InventoryModel[[#This Row],[SeverityRisk]]>=0.6), "CriticalUnderstock", AND(InventoryModel[[#This Row],[StockOutRisk]]="At Risk", InventoryModel[[#This Row],[SeverityRisk]]>=0.2, InventoryModel[[#This Row],[SeverityRisk]]<0.6), "WatchUnderstock", AND(InventoryModel[[#This Row],[StockOutRisk]]="OK", InventoryModel[[#This Row],[SeverityRisk]]<=-0.2, InventoryModel[[#This Row],[SeverityRisk]]>-0.75), "WatchOverstock", AND(InventoryModel[[#This Row],[StockOutRisk]]="OK", InventoryModel[[#This Row],[SeverityRisk]]<=-0.75), "CriticalOverstock", TRUE, "Optimal" )} -> CriticalOverstock | N25: =AVERAGEIFS(DemandHistory[AbsPctError],DemandHistory[SKUID],A25) -> 0.079621576 | O25: =InventoryModel[[#This Row],[StdDevWeeklyDemand]] / InventoryModel[[#This Row],[AvgWeeklyDemand]] -> 0.11949393 | P25: =_xlfn.XLOOKUP(A25, SKU_Master[SKUID], SKU_Master[Category], "Not Found", 0) -> Chains & Bars
